Workbook

Sheet 0_README
A1: DAY 22 • MONETIZATION & GTM — SÀNG LỌC CV BẰNG AI (SME VIỆT NAM)
A2: Ô VÀNG = giả định do người làm bài nhập · Ô XÁM = công thức, không sửa · Xanh = đạt ngưỡng · Đỏ = chưa đạt
A4: Sản phẩm (tên tạm) | B4: SàngCV — AI sàng lọc CV & lập shortlist có dẫn chứng | E4: Sản phẩm giả định của người làm bài; chưa có khách hàng hay prototype được đo.
A5: Người thực hiện | B5: Nguyễn Văn Sơn — 2A202602744
A6: Ngày chốt giá & số liệu | B6: 08/10/2026 | E6: Giá Gemini/Workable/Manatal/Fin được kiểm tra trực tiếp trên trang gốc ngày này (xem 6_Benchmarks).
A7: Tỷ giá giả định | B7: 26000 | C7: VND/USD | E7: Giả định làm tròn; cập nhật theo tỷ giá thực trước khi dùng số này với nhà đầu tư.
A8: Template gốc | B8: Không có | E8: File day22_monetization_model.xlsx và template .docx KHÔNG được cung cấp. File này dựng lại đúng 7 tab theo HUONG_DAN_LAB.md; bố cục ô không phải bản chính thức.
A10: 5 CON SỐ BẮT BUỘC (liên kết tới công thức)
A11: Cost/Job — COGS (₫) | B11: ='1_Cost_Job'!$B$94
A12: Cost/Job — đầy đủ 5 thành phần (₫) | B12: ='1_Cost_Job'!$B$95
A13: Giá sàn = 3 × COGS/job (₫) | B13: ='2_Pricing'!$B$22
A14: Giá bán: phí/shortlist (₫) | B14: ='2_Pricing'!$B$6
A15: Gross Margin (COGS) — mục tiêu ≥60% | B15: ='2_Pricing'!$B$15
A16: Margin đầy tải | B16: ='2_Pricing'!$B$16
A17: Breakeven containment (GM 60%) | B17: ='2_Pricing'!$B$39
A18: Containment giả định (chưa đo) | B18: ='1_Cost_Job'!$B$15
A19: Kênh đã chốt | B19: ='4_Channel_Fit'!$B$40
A20: THỨ TỰ LÀM
A21: • 1_Cost_Job → 2_Pricing → 3_Value_Metric → 4_Channel_Fit → 5_90Day_Plan → 6_Benchmarks (ghi ngày kiểm giá).
A22: • Trạng thái trung thực: GM theo COGS đạt, nhưng margin đầy tải còn mỏng và CHƯA có eval/pilot thật — xem 'Điểm chưa đạt' ở 5_90Day_Plan.
A23: • Mọi con số trong One-Pager truy được về một ô trong file này.

Sheet 1_Cost_Job
A1: 1 • COST / COMPLETED JOB (5 thành phần)
A2: Cost/Job = (API + Infra + HITL + Retry + Overhead) / số job HOÀN THÀNH. Tính bằng USD, đổi sang ₫ ở cuối tab.
A4: S1 · ĐỊNH NGHĨA 1 JOB
A5: Job | B5: 1 SHORTLIST HOÀN TẤT cho 1 vị trí tuyển dụng (requisition): AI xử lý toàn bộ CV nhận được, chấm theo rubric từ JD, trả top-N ứng viên kèm trích dẫn nguyên văn từ CV cho từng tiêu chí; recruiter đã xác nhận. | E5: Không phải '1 lần gọi API' hay '1 CV'. Khách coi shortlist là giá trị; đếm được tự động qua status.
A6: Điều kiện tính tiền (status = SHORTLIST_ACCEPTED) | B6: (1) ≥90% CV của requisition parse+chấm xong; (2) mỗi ứng viên top-N có ≥1 trích dẫn kiểm tra khớp CV cho mỗi tiêu chí; (3) recruiter bấm 'Chốt shortlist', hoặc xuất danh sách, hoặc mở ≥3 hồ sơ top trong 14 ngày. | E6: Chặt như định nghĩa 'resolution' của Intercom Fin: 'No further help is requested after Fin's last answer'.
A7: KHÔNG tính tiền | B7: Requisition bị hủy; shortlist bị recruiter gắn cờ 'sai'; hết 14 ngày không có tương tác nào. AI không bao giờ tự loại ứng viên: quyết định loại/tuyển luôn do người. | E7: Rủi ro thiên lệch trong tuyển dụng đã phân tích ở Lab 21 → bắt buộc human-in-the-loop ở quyết định cuối.
A8: Ngân sách của khách | B8: Ngân sách NHÂN SỰ/VẬN HÀNH tuyển dụng (thay phần việc sàng lọc sơ loại của HR executive/thực tập sinh) — không phải ngân sách phần mềm. | E8: Người ký: HR manager hoặc chủ doanh nghiệp SME 50–300 nhân sự.
A9: Biến thể HITL | B9: A – Bán phần mềm: recruiter của khách tự xử lý ca AI không chắc/parse lỗi. Vendor chỉ chịu chi phí QA/kiểm toán thiên lệch theo mẫu (tính vào COGS). | E9: Nếu chuyển sang bán kết quả (Biến thể B), mọi ca escalate thuộc COGS của vendor → Cost/Job cao hơn nhiều lần.
A11: S2 · VOLUME (kịch bản mục tiêu cuối tháng 3)
A12: Số khách trả tiền | B12: 8 | C12: khách | E12: Mục tiêu tháng 3 (5_90Day_Plan). GIẢ ĐỊNH — hiện 0 khách. Bảng ở 2_Pricing cho kết quả ở 3/5/8/12/20 khách.
A13: Requisition bắt đầu / khách / tháng | B13: 4 | C13: req | E13: SME 100–300 nhân sự, tuyển 3–5 vị trí/tháng. Cần xác minh qua phỏng vấn tháng 1.
A14: Số CV trung bình / requisition | B14: 300 | C14: CV | E14: Giả định; vị trí văn phòng đăng job board thường nhận vài trăm hồ sơ. Đo thật trong pilot.
A15: Tỷ lệ hoàn thành (containment) | B15: 0.8 | C15: tỷ lệ | E15: CHƯA đo. Là tỷ lệ requisition đạt SHORTLIST_ACCEPTED; cần eval 100 CV + pilot. Xem breakeven ở 2_Pricing.
A16: Requisition bắt đầu / tháng (attempts) | B16: =$B$12*$B$13 | C16: req
A17: Job hoàn thành / tháng (MẪU SỐ) | B17: =$B$16*$B$15 | C17: job | E17: Mẫu số là job HOÀN THÀNH, không phải job thử.
A18: Requisition thất bại / hủy | B18: =$B$16-$B$17 | C18: req | E18: Vẫn tốn token + hạ tầng + QA nhưng không thu tiền → nằm trong tử số.
A20: S3 · CHI PHÍ LLM — GEMINI 2.5 FLASH (giá list, kiểm tra 08/10/2026)
A21: Giá input | B21: 0.3 | C21: USD/1M | E21: ai.google.dev/gemini-api/docs/pricing — Standard paid, text/image/video.
A22: Giá output (đã gồm thinking token) | B22: 2.5 | C22: USD/1M | E22: Output tính cả thinking token.
A23: Giá cached input | B23: 0.03 | C23: USD/1M
A24: Phí lưu cache (explicit) | B24: 1 | C24: USD/1M token/giờ | E24: Phí lưu theo thời gian — dễ bị quên.
A25: Gemini 2.5 Flash-Lite input (bước kiểm tra trích dẫn) | B25: 0.1 | C25: USD/1M
A26: Gemini 2.5 Flash-Lite output | B26: 0.4 | C26: USD/1M
A27: Giá embedding (text) | B27: 0.2 | C27: USD/1M | E27: Gemini Embedding 2 — Standard text; dùng để khử trùng lặp CV.
A28: Token system + JD + rubric | B28: 3000 | C28: token/CV | E28: Giả định; đo bằng usage_metadata.
A29: Token CV (đã trích text) | B29: 1500 | C29: token/CV | E29: Giả định CV 2 trang.
A30: Token output JSON (điểm + trích dẫn) | B30: 700 | C30: token/CV
A31: Token thinking | B31: 1000 | C31: token/CV | E31: Chưa đo; tính theo giá output.
A32: Dùng explicit cache? (1=có, 0=không) | B32: 0 | C32: cờ | E32: Chọn 0 vì phí lưu cache > tiết kiệm (xem dòng '% tiết kiệm nhờ cache').
A33: Tỷ lệ cache hit nếu dùng cache | B33: 0.9 | C33: tỷ lệ
A34: Giờ lưu cache phân bổ / CV | B34: 0.6 | C34: giờ | E34: Giả định cache JD 24h, ~40 CV/JD/ngày → 24/40 = 0,6h.
A35: Bước kiểm tra trích dẫn — input | B35: 2200 | C35: token/CV | E35: CV + JSON đưa vào Flash-Lite để xác minh trích dẫn có thật trong CV (chống bịa).
A36: Bước kiểm tra trích dẫn — output | B36: 200 | C36: token/CV
A37: Tỷ lệ CV scan/ảnh cần OCR | B37: 0.25 | C37: tỷ lệ | E37: Giả định; CV Việt Nam hay là PDF scan/ảnh.
A38: OCR — token input ảnh | B38: 516 | C38: token/CV | E38: Giả định 2 trang × 258; cần xác minh bằng usage_metadata.
A39: OCR — token output text | B39: 1500 | C39: token/CV
A40: Token embedding / CV | B40: 1500 | C40: token
A41: Tạo rubric từ JD + báo cáo shortlist — input | B41: 8000 | C41: token/req | E41: 1 lần / requisition.
A42: Tạo rubric từ JD + báo cáo shortlist — output | B42: 3000 | C42: token/req
A43: Dùng Batch API? (1=có, 0=không) | B43: 0 | C43: cờ | E43: Shortlist không cần realtime (SLA vài giờ) → Batch (−50%) khả thi; base case để 0 (bảo thủ).
...

Sheet 2_Pricing
A1: 2 • PRICING, GROSS MARGIN & STRESS TEST
A2: GM chuẩn = (Doanh thu − COGS)/Doanh thu, COGS = API + Infra + HITL + Retry. Overhead tách riêng và báo cáo margin đầy tải.
A4: OFFER (Hybrid)
A5: Phí nền / khách / tháng | B5: 500000 | C5: ₫ | E5: Gồm: thiết lập rubric, onboarding, báo cáo kiểm toán thiên lệch hàng tháng. CHƯA kiểm chứng willingness-to-pay.
A6: Phí / shortlist hoàn tất | B6: 800000 | C6: ₫ | E6: ≈ 2.667 ₫/CV ở 300 CV/req — thấp hơn Workable (0,12 USD/CV).
A7: Cam kết hoàn phí | B7: Hoàn 50% phí nền nếu tháng đó <1 shortlist hoàn tất | E7: Giảm cảm giác 'bị phạt' tháng thấp điểm.
A9: DOANH THU & MARGIN
A10: Doanh thu / tháng | B10: =$B$5*'1_Cost_Job'!$B$12+$B$6*'1_Cost_Job'!$B$17 | C10: ₫
A11: Doanh thu / tháng (USD) | B11: =$B$10/'0_README'!$B$7 | C11: USD
A12: Doanh thu hiệu dụng / job (gồm phí nền) | B12: =$B$10/'1_Cost_Job'!$B$17 | C12: ₫/job
A13: COGS / tháng | B13: ='1_Cost_Job'!$B$83*'0_README'!$B$7 | C13: ₫
A14: Overhead / tháng | B14: ='1_Cost_Job'!$B$84*'0_README'!$B$7 | C14: ₫
A15: GROSS MARGIN (theo COGS) | B15: =($B$10-$B$13)/$B$10 | C15: tỷ lệ | E15: Mục tiêu ≥60%. Xanh nếu đạt.
A16: Margin đầy tải (sau Overhead) | B16: =($B$10-$B$13-$B$14)/$B$10 | C16: tỷ lệ | E16: KHÔNG gọi là GM kế toán. Rất mỏng ở 8 khách.
A17: Ngưỡng GM | B17: 0.6 | C17: tỷ lệ
A18: Trạng thái GM | B18: =IF($B$15>=$B$17,"ĐẠT ≥60%","CHƯA ĐẠT")
A19: GM có đáng ngờ không (>85%)? | B19: =IF($B$15>0.85,"ĐÁNG NGỜ — thiếu chi phí","Không (<85%)")
A21: GIÁ SÀN = 3 × COST/JOB
A22: Giá sàn theo COGS/job | B22: =3*'1_Cost_Job'!$B$94 | C22: ₫/job
A23: Giá sàn theo Cost/Job đầy đủ (5 thành phần) | B23: =3*'1_Cost_Job'!$B$95 | C23: ₫/job
A24: Phí/shortlist ≥ giá sàn COGS? | B24: =IF($B$6>=$B$22,"ĐẠT","KHÔNG ĐẠT")
A25: Phí/shortlist ≥ giá sàn đầy đủ? | B25: =IF($B$6>=$B$23,"ĐẠT","KHÔNG ĐẠT — overhead còn gánh trên ít khách") | E25: Thừa nhận: ở 8 khách, Cost/Job đầy đủ xấp xỉ giá bán. Cần ≥12–20 khách để overhead/job giảm (bảng quy mô bên dưới).
A27: NEO GIÁ TRẦN
A28: Phút sàng lọc thủ công / CV | B28: 4 | C28: phút | E28: Giả định: đọc, so JD, ghi vào Excel. Đo bằng time-study 5 HR trong tháng 1.
A29: Phút recruiter xem top-10 sau khi có AI | B29: 50 | C29: phút/req | E29: 10 hồ sơ × 5 phút.
A30: Lương HR executive (giả định) | B30: 12000000 | C30: ₫/tháng | E30: Giả định; chưa phỏng vấn.
A31: Giờ làm / tháng | B31: 176 | C31: giờ
A32: Chi phí nhân công sàng lọc / requisition | B32: ='1_Cost_Job'!$B$14*$B$28/60*$B$30/$B$31 | C32: ₫
A33: Neo theo nhân công: 50% – 70% | B33: =TEXT(0.5*$B$32,"#,##0")&" – "&TEXT(0.7*$B$32,"#,##0")&" ₫"
A34: Giá/shortlist ÷ nhân công thay thế | B34: =$B$6/$B$32 | C34: tỷ lệ | E34: Nằm trong 50–70% = hợp lệ theo neo nhân công.
A35: Giá trị tiết kiệm / requisition | B35: =$B$32-$B$29/60*$B$30/$B$31 | C35: ₫
A36: Neo theo giá trị: 10% – 25% giá trị tiết kiệm | B36: =TEXT(0.1*$B$35,"#,##0")&" – "&TEXT(0.25*$B$35,"#,##0")&" ₫" | E36: Giá bán NẰM TRÊN dải này vì mới tính tiết kiệm thời gian, chưa tính lợi ích tuyển nhanh/ít bỏ sót. Phải kiểm bằng thử giá trong pilot (3 mức giá).
A38: STRESS TEST — BREAKEVEN CONTAINMENT
A39: Containment tối thiểu để GM ≥ 60% | B39: =MAX(0,($B$13/(1-$B$17)-$B$5*'1_Cost_Job'!$B$12)/($B$6*'1_Cost_Job'!$B$16)) | C39: tỷ lệ | E39: Đại số: Rev ≥ COGS/(1−0,6) ⇒ c ≥ (COGS/0,4 − phí nền×khách)/(giá×attempts). COGS không đổi theo c vì mọi requisition thử đều tốn chi phí.
A40: Containment giả định hiện tại | B40: ='1_Cost_Job'!$B$15 | C40: tỷ lệ | E40: ƯỚC TÍNH, chưa có eval — deadline eval ở 5_90Day_Plan.
A41: Biên an toàn | B41: ='1_Cost_Job'!$B$15-$B$39 | C41: điểm %
A42: Nếu thấp hơn ngưỡng sẽ làm gì? | B42: Tăng containment (cải thiện parse/OCR + rubric) trước; nếu vẫn thiếu thì tăng phí/shortlist; KHÔNG chuyển sang Biến thể B (nuốt HITL vào COGS).
A44: Độ nhạy theo containment
A45: Containment | B45: Job hoàn thành | C45: Cost/job (COGS, ₫) | E45: GM
A46: 0.5 | B46: ='1_Cost_Job'!$B$16*A46 | C46: =$B$13/B46 | E46: =($B$5*'1_Cost_Job'!$B$12+$B$6*B46-$B$13)/($B$5*'1_Cost_Job'!$B$12+$B$6*B46)
...

Sheet 3_Value_Metric
A1: 3 • VALUE METRIC — ATTRIBUTION × AUTONOMY
A2: Chấm theo THỰC TẾ HÔM NAY (1 = hoàn toàn không, 5 = hoàn toàn có). Không chấm theo kế hoạch quý sau.
A4: ATTRIBUTION — đo được rằng kết quả do AI tạo ra?
A5: Job có ID duy nhất và status ghi tự động? | B5: 5 | E5: Thiết kế: SHORTLIST_ACCEPTED + requisition_id.
A6: Có audit trail (model, rubric, version, trích dẫn) cho mỗi shortlist? | B6: 4 | E6: Thiết kế sẵn; chưa triển khai production.
A7: Có eval/ground truth so với recruiter? | B7: 2 | E7: CHƯA có bộ eval thật — điểm thấp, trung thực.
A8: Khách tự kiểm chứng được job (xem trích dẫn gốc)? | B8: 4 | E8: Mỗi điểm có trích dẫn nguyên văn từ CV.
A9: Ít rủi ro tranh chấp định nghĩa job? | B9: 3 | E9: Còn rủi ro: recruiter không bấm chốt (đã thêm quy tắc mở ≥3 hồ sơ).
A10: Attribution (tổng /25) | B10: =SUM(B5:B9) | C10: /25 | E10: ≥15 = cao.
A12: AUTONOMY — AI tự chạy tới kết quả mà không cần người?
A13: AI hoàn tất job không cần người xác nhận? | B13: 2 | E13: Cần recruiter chốt shortlist.
A14: AI tự quyết định loại/tuyển ứng viên? | B14: 1 | E14: CẤM theo thiết kế (rủi ro thiên lệch, Lab 21).
A15: Tỷ lệ job hoàn tất không cần can thiệp ngoài thao tác chốt? | B15: 3 | E15: Chưa đo; ước tính ~80%.
A16: Chạy liên tục không cần người kích hoạt? | B16: 3 | E16: Chạy khi có CV mới, nhưng JD/rubric do người duyệt.
A17: Tự xử lý ngoại lệ (CV lỗi, timeout)? | B17: 3 | E17: Retry + hàng đợi lỗi; ca khó chuyển cho recruiter.
A18: Autonomy (tổng /25) | B18: =SUM(B13:B17) | C18: /25 | E18: ≥15 = cao.
A20: Gợi ý của ma trận | B20: =IF(AND($B$10>=15,$B$18>=15),"Outcome",IF($B$10>=15,"Usage",IF($B$18>=15,"Usage","Seat / Hybrid"))) | E20: Attribution cao + Autonomy thấp → Usage.
A21: Value Metric đã chốt | B21: HYBRID: 500.000 ₫/khách/tháng + 800.000 ₫/shortlist hoàn tất | E21: Khác gợi ý Usage thuần ở chỗ có thêm phí nền (lý do thị trường bên dưới).
A22: Decision Note (3 câu) | B22: 1) Tôi chọn Hybrid: phí nền theo khách + phí theo shortlist hoàn tất (SHORTLIST_ACCEPTED). 2) Attribution ở mức cao (18/25: ID duy nhất, audit trail, trích dẫn kiểm chứng được) nhưng Autonomy thấp (12/25: AI không được tự loại ứng viên, recruiter luôn chốt) và CHƯA có eval → vì vậy KHÔNG chọn Outcome (per-hire) mà dùng đơn vị usage gắn với kết quả đo được. 3) Tôi lệch khỏi gợi ý Usage thuần vì thị trường SME Việt Nam: các ATS bán cho SME đều tính phí nền theo công ty hoặc theo ghế (Workable 299 USD/tháng/công ty; Manatal 15–55 USD/ghế/tháng), khách quen ngân sách cố định và chưa quen trả theo kết quả; phí nền cũng chi trả chi phí cố định (infra + QA) khi doanh thu theo job còn nhỏ. | E22: Lý do thị trường hợp lệ, không phải 'thấy hợp hơn'. Giả thuyết cần kiểm bằng phỏng vấn tháng 1.
A23: Chống tính tiền hai lần / gian lận | B23: Mỗi requisition_id chỉ tính 1 lần; sửa JD làm đổi >30% rubric mới mở job mới; giới hạn 500 CV/requisition, vượt thì 1.500 ₫/CV; theo dõi tỷ lệ requisition bị hủy sau khi có shortlist (nghi ngờ né phí). | E23: Rủi ro khách 'né phí' bằng cách không chốt/hủy → đã thêm quy tắc auto-confirm khi xem ≥3 hồ sơ.
A25: BENCHMARK NGƯỢC — 3 SẢN PHẨM THẬT (kiểm tra 08/10/2026)
A26: 1. Workable (AI screening) | B26: Standard 299 USD/tháng/công ty. AI Agent tính credit: 1 credit / lần sàng lọc ứng viên; gói bổ sung 5.000 credit = 600 USD → 0,12 USD/credit ≈ 0,12 USD/CV. | E26: https://www.workable.com/pricing
A27: 2. Manatal (ATS + AI recommendation) | B27: Tính theo ghế: Professional 15 USD/user/tháng (trả theo năm), Enterprise 35, Enterprise Plus 55; AI recommendation có trong mọi gói. | E27: https://www.manatal.com/pricing
A28: 3. Intercom Fin (tham chiếu Outcome) | B28: 0,99 USD/outcome; resolution = 'No further help is requested after Fin's last answer'; tối thiểu 50 outcome/tháng. Outcome chỉ hợp khi AI tự chạy (autonomy cao) — khác SàngCV. | E28: https://fin.ai/pricing/
A29: Giá hiệu dụng của SàngCV / CV xử lý | B29: ='2_Pricing'!$B$11/('1_Cost_Job'!$B$16*'1_Cost_Job'!$B$14) | C29: USD/CV | E29: So với Workable 0,12 USD/CV.

Sheet 4_Channel_Fit
A1: 4 • CHANNEL FIT — KÊNH DUY NHẤT CHO 90 NGÀY ĐẦU
A2: Pain Moment quyết định kênh; kênh phải nuôi nổi bằng số học (Affordability Test).
A4: AFFORDABILITY TEST
A5: Phân khúc | B5: SMB | E5: SME 50–300 nhân sự → CAC payback < 12 tháng.
A6: CAC payback cho phép | B6: 12 | C6: tháng | E6: SMB <12 · Mid-market <18 · Enterprise <24 (theo HUONG_DAN_LAB).
A7: ARPU / khách / tháng | B7: ='2_Pricing'!$B$11/'1_Cost_Job'!$B$12 | C7: USD | E7: Gồm phí nền + phí shortlist.
A8: NGÂN SÁCH CAC / khách | B8: =$B$7*'2_Pricing'!$B$15*$B$6 | C8: USD | E8: Công thức: ARPU × GM × số tháng payback.
A10: CÔNG CỤ 1 — NGƯỠNG SÀN INSIDE SALES (Tunguz)
A11: ACV (ARPU × 12) | B11: =$B$7*12 | C11: USD
A12: Quota AE / năm | B12: 200000 | C12: USD | E12: Giả định quota inside-sales SMB.
A13: Số deal AE phải chốt / năm | B13: =$B$12/$B$11 | C13: deal
A14: Ngày làm việc / năm | B14: 240 | C14: ngày
A15: Số deal / AE / ngày | B15: =$B$13/$B$14 | C15: deal/ngày | E15: ≤~1 → khả thi về số học; >1 → không chạy được.
A16: Kết luận số học | B16: =IF($B$15<=1,"Khả thi về số học — nhưng xem CAC bên dưới","KHÔNG CHẠY ĐƯỢC")
A18: CÔNG CỤ 3 — CAC THỰC TẾ SALES-LED (ICONIQ 2026)
A19: Cost per opportunity (SMB) | B19: 6300 | C19: USD | E19: Theo HUONG_DAN_LAB: 6.300 · 8.000 · 11.200 USD theo phân khúc (giả định thứ tự SMB·Mid·Ent). Chưa tra lại nguồn gốc ICONIQ.
A20: Win rate giả định | B20: 0.2 | C20: tỷ lệ | E20: Giả định.
A21: CAC thực tế Sales-Led ≈ CPO / win rate | B21: =$B$19/$B$20 | C21: USD
A22: Lệch so với ngân sách CAC | B22: =$B$21/$B$8 | C22: lần | E22: → Sales-Led full-cycle KHÔNG nuôi nổi.
A24: CAC ƯỚC TÍNH CỦA PLG (giả thuyết cần kiểm trong tháng 2–3)
A25: Chi phí / lượt đăng ký dùng thử | B25: 12 | C25: USD | E25: GIẢ ĐỊNH (quảng cáo cho HR SME). Chưa thử.
A26: Tỷ lệ đăng ký → trả tiền | B26: 0.06 | C26: tỷ lệ | E26: GIẢ ĐỊNH. Điều kiện hủy kênh: <3%.
A27: CAC PLG ước tính | B27: =$B$25/$B$26 | C27: USD
A28: CAC PLG / ngân sách CAC | B28: =$B$27/$B$8 | C28: lần | E28: <1 = nuôi nổi (nếu giả định đúng).
A30: SCORECARD 3 KÊNH (6 tiêu chí × 1–5)
A31: Tiêu chí | B31: PLG | C31: Sales-Led | E31: Partner-Led
A32: ARPU phù hợp với cách bán | B32: 4 | C32: 3 | E32: 5
A33: CAC nuôi nổi theo ngân sách | B33: 5 | C33: 1 | E33: 4
A34: Khớp Pain Moment (ngay trong hộp thư/bảng tính) | B34: 5 | C34: 3 | E34: 3
A35: Tốc độ có 5 khách trả tiền đầu tiên | B35: 3 | C35: 4 | E35: 2
A36: Năng lực đội 1–4 người | B36: 4 | C36: 2 | E36: 3
A37: Ít phụ thuộc bên thứ ba | B37: 4 | C37: 5 | E37: 2
A38: TỔNG /30 | B38: =SUM(B32:B37) | C38: =SUM(C32:C37) | E38: =SUM(E32:E37)
A40: KÊNH ĐÃ CHỐT (chỉ 1) | B40: =IF(AND(B38>=C38,B38>=E38),"PLG",IF(C38>=E38,"Sales-Led","Partner-Led")) | E40: Điểm cao nhất. Gắn với số: CAC PLG ước tính thấp hơn ngân sách, Sales-Led lệch gấp nhiều lần.
A41: Vì sao không Partner-Led | B41: Chưa có tên đối tác cụ thể và chưa nói chuyện với ai → theo quy tắc lab 'Partner-Led không có tên công ty thì chưa phải là kênh'. Có thể thăm dò một nền tảng ATS/tuyển dụng nội địa sau tháng 3 (CHƯA liên hệ, chỉ là giả thuyết). | E41: Không chạy song song nhiều kênh.
A42: Rủi ro kênh PLG | B42: Add-on Gmail đọc thư thuộc nhóm 'restricted scope' của Google → có thể cần xác minh OAuth + đánh giá bảo mật bên thứ ba (chi phí/thời gian CHƯA có báo giá). Giảm thiểu cho MVP: nhận CV qua chuyển tiếp email/thư mục Drive, không đọc cả hộp thư. | E42: Cần xác minh chính sách hiện hành của Google trước khi cam kết.
A43: Pain Moment | B43: 9h sáng thứ Hai, HR executive mở Gmail/Google Sheets sau cuối tuần đăng tin và thấy 200–300 CV mới; đang kéo từng file PDF vào Excel để chấm tay theo JD. | E43: Đủ 3 phần: mấy giờ + đang làm gì + dùng app nào.
A44: Điểm nhúng | B44: Hộp thư HR (chuyển tiếp CV tới địa chỉ riêng của SàngCV) + Google Sheets add-on trả bảng shortlist ngay trong file họ đang dùng. Không bắt tải app mới. | E44: Nhúng vào thói quen cũ.

Sheet 5_90Day_Plan
A1: 5 • 90-DAY PLAN & EVIDENCE PACK
A2: Mốc ngày là KẾ HOẠCH dự kiến, chưa phải dữ liệu đã thực hiện. Ô nào chưa có đều ghi người phụ trách + deadline.
A4: PAIN MOMENT & ĐIỂM NHÚNG
A5: Pain Moment | B5: 9h sáng thứ Hai · HR executive đang chấm tay 200–300 CV sau cuối tuần đăng tin · trong Gmail/Excel | E5: Công thức 3 phần: mấy giờ + đang làm gì + app nào.
A6: Điểm nhúng | B6: Địa chỉ email chuyển tiếp CV + Google Sheets add-on (kênh PLG). | E6: Không bắt khách mở tab mới, tải app mới.
A7: Kênh (liên kết 4_Channel_Fit) | B7: ='4_Channel_Fit'!$B$40
A9: KẾ HOẠCH 90 NGÀY (người phụ trách: Nguyễn Văn Sơn)
A10: Giai đoạn | B10: Mục tiêu & cơ chế | C10: KPI (số) | D10: Phụ trách | E10: Điều kiện dừng / sửa
A11: Tháng 1 (11/2026) — Hiểu sâu | B11: Phỏng vấn 15 HR của SME; time-study 5 HR (phút/CV); làm tận tay 3 pilot miễn phí × 2 requisition; thử 3 mức giá. | C11: ≥15 phỏng vấn; 3 pilot; ≥6 shortlist; đo containment + giá chấp nhận | D11: Sơn | E11: Nếu <2/15 HR sẵn sàng trả ≥500k ₫/tháng → đổi mô hình giá/đối tượng.
A12: Tháng 2–3 (12/2026–01/2027) — Đòn bẩy qua kênh PLG | B12: Landing page + nhận CV qua email forward + Sheets add-on; shortlist đầu tiên miễn phí; nhân rộng bằng nội dung & giới thiệu từ pilot. | C12: ≥120 lượt đăng ký dùng thử; activation ≥40%; 8 khách trả tiền (mục tiêu cuối tháng 3) | D12: Sơn | E12: Nếu đăng ký→trả tiền <3% sau 60 ngày hoặc CAC PLG > ngân sách CAC → dừng kênh, xét lại.
A13: Tháng 4+ (02/2027) — Mở rộng có điều kiện | B13: Chỉ mở ngách kế tiếp (tuyển dụng hàng loạt: bán lẻ/F&B) khi thắng tuyệt đối ngách SME văn phòng; sau đó mới thăm dò đối tác ATS. | C13: Containment ≥ ngưỡng breakeven; ≥8 khách; GM ≥60% đo thật | D13: Sơn | E13: Không mở rộng nếu eval chưa đạt.
A15: EVIDENCE PACK
A16: Tài sản | B16: Hiện có gì / sẽ có gì | C16: Đo bằng | D16: Deadline | E16: Phụ trách & ghi chú
A17: Eval Results | B17: CHƯA CÓ. Kế hoạch: bộ 100 CV ẩn danh/tổng hợp có nhãn của 2 recruiter. Chỉ số: recall top-10 so với recruiter (mục tiêu ≥85%), tỷ lệ trích dẫn khớp CV (≥95%), tỷ lệ parse thành công (≥92%), tỷ lệ chọn theo nhóm giới/tuổi (quy tắc 4/5 ≥0,8). | C17: Script eval + 2 người gán nhãn | D17: 25/10/2026 | E17: Sơn. Hiện CHƯA có số nào; containment 80% là giả định.
A18: Procurement Q&A | B18: CHƯA CÓ văn bản. Trả lời bằng văn bản: (1) AI có bịa không, sai thì trách nhiệm ra sao (trích dẫn bắt buộc + người chốt)? (2) Dữ liệu CV có bị dùng để huấn luyện mô hình không (phải xác nhận cấu hình API/gói)? (3) Startup dừng hoạt động thì dữ liệu ứng viên ở đâu (xuất + xóa trong 30 ngày)? Thêm: căn cứ & thời hạn lưu dữ liệu cá nhân ứng viên. | C18: Tài liệu 2 trang + chính sách dữ liệu | D18: 20/10/2026 | E18: Sơn; cần chuyên gia pháp lý xác nhận phần dữ liệu cá nhân. Không khẳng định điều khoản của nhà cung cấp LLM khi chưa kiểm cấu hình.
A19: Pilot Report | B19: CHƯA CÓ pilot. Mẫu: '__ tuần, __ requisition, __ CV, tỷ lệ shortlist được chốt __%, thời gian tiết kiệm __ giờ'. | C19: Log hệ thống + khảo sát HR | D19: 10/12/2026 | E19: Sơn; phải liên hệ khách pilot trước 05/11/2026 (hiện chưa liên hệ ai).
A21: ĐIỂM CHƯA ĐẠT / THỪA NHẬN
A22: Chưa có dữ liệu thật | B22: Không có eval, pilot hay khách hàng; mọi containment/volume/giá là giả định.
A23: Margin đầy tải thấp | B23: Ở 8 khách margin đầy tải chỉ vài %, Cost/Job đầy đủ xấp xỉ giá bán; cần ≥12–20 khách (2_Pricing) hoặc giảm overhead.
A24: Giá chưa kiểm chứng | B24: Giá nằm trên dải neo giá trị 10–25%; chỉ nằm trong dải neo nhân công 50–70% theo lương giả định.
A25: Rủi ro pháp lý | B25: Tuyển dụng bằng AI là lĩnh vực nhạy cảm (Lab 21); cần rà soát pháp lý dữ liệu cá nhân & quy định AI trước khi bán.
A26: Template | B26: Không có file xlsx/docx gốc của lab; file này dựng lại theo hướng dẫn.

Sheet 6_Benchmarks
A1: 6 • BENCHMARK & NGUỒN (chỉ đọc)
A2: Cột D = ngày kiểm tra trực tiếp trên trang gốc. ⏳ = giá có thể đổi, kiểm lại trước khi dùng.
A4: Hạng mục | B4: Giá trị | C4: Đơn vị | D4: Ngày kiểm | E4: Nguồn / ghi chú
A5: ⏳ Gemini 2.5 Flash — input | B5: 0.3 | C5: USD/1M | D5: 08/10/2026 | E5: https://ai.google.dev/gemini-api/docs/pricing (Standard paid)
A6: ⏳ Gemini 2.5 Flash — output (gồm thinking) | B6: 2.5 | C6: USD/1M | D6: 08/10/2026 | E6: https://ai.google.dev/gemini-api/docs/pricing
A7: ⏳ Gemini 2.5 Flash — cached input | B7: 0.03 | C7: USD/1M | D7: 08/10/2026 | E7: https://ai.google.dev/gemini-api/docs/pricing
A8: ⏳ Gemini — phí lưu cache | B8: 1 | C8: USD/1M token-giờ | D8: 08/10/2026 | E8: https://ai.google.dev/gemini-api/docs/pricing
A9: ⏳ Gemini 2.5 Flash — Batch input / output | B9: 0,15 / 1,25 | C9: USD/1M | D9: 08/10/2026 | E9: https://ai.google.dev/gemini-api/docs/pricing
A10: ⏳ Gemini 2.5 Flash-Lite — input / output | B10: 0,10 / 0,40 | C10: USD/1M | D10: 08/10/2026 | E10: https://ai.google.dev/gemini-api/docs/pricing
A11: ⏳ Gemini Embedding 2 — text | B11: 0.2 | C11: USD/1M | D11: 08/10/2026 | E11: https://ai.google.dev/gemini-api/docs/pricing
A12: Workable — Standard | B12: 299 | C12: USD/tháng/công ty | D12: 08/10/2026 | E12: https://www.workable.com/pricing
A13: Workable — AI credit (5.000 credit = 600 USD) | B13: 0.12 | C13: USD/credit | D13: 08/10/2026 | E13: https://www.workable.com/pricing — 1 credit/lần sàng lọc ứng viên
A14: Manatal — Professional / Enterprise / Ent. Plus | B14: 15 / 35 / 55 | C14: USD/user/tháng | D14: 08/10/2026 | E14: https://www.manatal.com/pricing (trả theo năm)
A15: Intercom Fin | B15: 0.99 | C15: USD/outcome | D15: 08/10/2026 | E15: https://fin.ai/pricing/ — tối thiểu 50 outcome/tháng
A16: ICONIQ 2026 cost per opportunity (SMB·Mid·Ent) | B16: 6.300 · 8.000 · 11.200 | C16: USD | D16: — | E16: Lấy từ HUONG_DAN_LAB.md; CHƯA tra lại nguồn gốc
A17: Tỷ giá | B17: 26000 | C17: VND/USD | D17: — | E17: Giả định làm tròn
A18: Bối cảnh pháp lý tuyển dụng-AI | B18: Xem Lab 21 | D18: — | E18: Báo cáo Lab 21 của người làm bài (Luật AI 134/2025/QH15; Luật BVDLCN 91/2025/QH15) — chưa kiểm tra lại, cần chuyên gia pháp lý xác nhận
